Workbook

Sheet 版本信息
B2: 制造执行系统迭代2冲刺待办列表跟踪表
B3: 西安优加青软数字技术有限公司 技术支持部审定
B5: 版本 | C5: 日期 | D5: 更新人员 | E5: 更新类型 | F5: 更新内容说明 | G5: 更新范围 | H5: 联动变更文档 | I5: 审核人员 | J5: 备注
B6: V1.1.0 | C6: 46028 | D6: 王强 | E6: 初始化 | F6: 初始版本发布，完成文档核心内容编制 | G6: 版本信息、正文、使用说明 | H6: 无 | I6: 李静 | J6: 初始基础版本
B14: *本文件仅限西安优加青软数字技术有限公司和被呈送方内部使用，未经许可，请勿扩散到第三方。

Sheet 交付物清单
A1: 交付物 ID | B1: 交付物名称 | C1: 所属模块 | D1: 交付类型 | E1: 责任认领人 | F1: 核心验收标准 | G1: 计划交付时间 | H1: 实际交付时间 | I1: 交付状态 | J1: 更新记录（李静维护） | K1: 备注 | L1: 关联待办项ID | M1: 关联用户故事ID
A2: D-F-024 | B2: 系统参数修改（可运行） | C2: 系统管理（SM） | D2: 功能交付物 | E2: 王强 | F2: 1. 参数值与类型匹配；2. 保存后生效值一致；3. 操作有日志记录；4. 禁用时弹出确认提示；5. 核心参数不可修改 | G2: 46035 | H2: 46035 | I2: 验收通过 | J2: 1.01-06 17:00（第 1 周）：初始 “待交付”；2.01-08 17:00（第 1 周）：依赖迭代 1 基础功能，启动开发，状态更新为 “开发中”；3.01-12 17:00（第 1 周）：开发完成，状态更新为 “待验收”； 4.01-13 17:00（第 2 周）：张伟验收通过，状态更新为 “验收通过” | K2: 部分参数修改后需重启系统 | L2: PB-SM-019 | M2: MES-SM-19
A3: D-F-025 | B3: 系统参数删除（可运行） | C3: 系统管理（SM） | D3: 功能交付物 | E3: 王强 | F3: 1. 删除前弹出确认提示；2. 仅禁用状态可删除；3. 核心参数禁止删除；4. 删除后不再显示；5. 操作有日志记录 | G3: 46036 | H3: 46036 | I3: 验收通过 | J3: 1.01-06 17:00（第 1 周）：初始 “待交付”；2.01-09 17:00（第 1 周）：依赖迭代 1 基础功能，启动开发，状态更新为 “开发中”；3.01-13 17:00（第 2 周）：开发完成，状态更新为 “待验收”； 4.01-14 17:00（第 2 周）：张伟验收通过，状态更新为 “验收通过” | K3: 建议删除前备份配置信息 | L3: PB-SM-020 | M3: MES-SM-20
A4: D-F-054 | B4: 物料分类新增（可运行） | C4: 基础数据（BD） | D4: 功能交付物 | E4: 王强 | F4: 1. 编码重复提示；2. 同一上级分类下名称唯一；3. 名称、编码为必填项；4. 保存后树形结构同步显示；5. 操作有日志记录 | G4: 46034 | H4: 46034 | I4: 验收通过 | J4: 1.01-06 17:00（第 1 周）：初始 “待交付”；2.01-10 17:00（第 1 周）：王强反馈开发中，状态更新为 “开发中”；3.01-11 17:00（第 1 周）：开发完成，状态更新为 “待验收”；4.01-12 17:00（第 1 周）：张伟验收通过 | K4: 分类编码建议采用 “MATC + 层级 + 序号” 格式 | L4: PB-BD-017 | M4: MES-BD-17
A5: D-F-055 | B5: 物料分类查询（可运行） | C5: 基础数据（BD） | D5: 功能交付物 | E5: 王强 | F5: 1. 编码精确匹配，名称模糊匹配；2. 按上级分类筛选；3. 树形结构展示，支持展开 / 折叠；4. 无结果提示对应信息；5. 支持按排序序号排序 | G5: 46035 | H5: 46035 | I5: 验收通过 | J5: 1.01-06 17:00（第 1 周）：初始 “待交付”；2.01-11 17:00（第 1 周）：依赖物料分类新增功能完成，启动开发，状态 “开发中”；3.01-12 17:00（第 1 周）：开发完成，状态更新为 “待验收”；4.01-13 17:00（第 1 周）：张伟验收通过 | K5: 点击分类名称可查看物料列表 | L5: PB-BD-018 | M5: MES-BD-18
A6: D-F-056 | B6: 物料分类修改（可运行） | C6: 基础数据（BD） | D6: 功能交付物 | E6: 王强 | F6: 1. 编码不可修改；2. 同一上级分类下名称唯一；3. 已关联物料的不可调整上级分类；4. 保存后树形结构同步更新；5. 操作有日志记录 | G6: 46036 | H6: 46036 | I6: 验收通过 | J6: 1.01-06 17:00（第 1 周）：初始 “待交付”；2.01-12 17:00（第 1 周）：依赖物料分类新增功能完成，启动开发，状态 “开发中”；3.01-13 17:00（第 1 周）：开发完成，状态更新为 “待验收”；4.01-14 17:00（第 1 周）：张伟验收通过 | K6: 排序序号越小，展示越靠前 | L6: PB-BD-019 | M6: MES-BD-19
A7: D-F-057 | B7: 物料分类删除（可运行） | C7: 基础数据（BD） | D7: 功能交付物 | E7: 王强 | F7: 1. 删除前弹出确认提示；2. 含子分类或关联物料的禁止删除；3. 删除后树形结构不再显示；4. 操作有日志记录；5. 仅空分类可删除 | G7: 46037 | H7: 46037 | I7: 验收通过 | J7: 1.01-06 17:00（第 1 周）：初始 “待交付”；2.01-13 17:00（第 1 周）：依赖物料分类新增功能完成，启动开发，状态 “开发中”；3.01-14 17:00（第 1 周）：开发完成，状态更新为 “待验收”；4.01-15 17:00（第 1 周）：张伟验收通过 | K7: 建议删除前确认无关联数据 | L7: PB-BD-020 | M7: MES-BD-20
A8: D-F-058 | B8: 物料信息新增（可运行） | C8: 基础数据（BD） | D8: 功能交付物 | E8: 陈明 | F8: 1. 必填项为空提示；2. 编码唯一；3. 计量单位需有效；4. 保存后列表同步显示；5. 操作有日志记录 | G8: 46039 | H8: 46039 | I8: 验收通过 | J8: 1.01-06 17:00（第 1 周）：初始 “待交付”；2.01-15 17:00（第 2 周）：依赖物料分类、计量单位功能完成，启动开发，状态 “开发中”；3.01-16 17:00（第 2 周）：开发完成，状态更新为 “待验收”；4.01-17 17:00（第 2 周）：张伟验收通过 | K8: 物料编码建议采用 “分类编码 + 6 位序号” 格式 | L8: PB-BD-021 | M8: MES-BD-21
A9: D-F-059 | B9: 物料信息查询（可运行） | C9: 基础数据（BD） | D9: 功能交付物 | E9: 陈明 | F9: 1. 编码精确匹配，名称 / 规格模糊匹配；2. 多条件组合筛选；3. 分页展示（默认 20 条）；4. 无结果提示对应信息；5. 支持按编码排序 | G9: 46040 | H9: 46040 | I9: 验收通过 | J9: 1.01-06 17:00（第 1 周）：初始 “待交付”；2.01-16 17:00（第 2 周）：依赖物料信息新增功能完成，启动开发，状态 “开发中”；3.01-17 17:00（第 2 周）：开发完成，状态更新为 “待验收”；4.01-18 17:00（第 2 周）：张伟验收通过 | K9: 支持导出物料列表（Excel 格式） | L9: PB-BD-022 | M9: MES-BD-22
A10: D-F-060 | B10: 物料信息修改（可运行） | C10: 基础数据（BD） | D10: 功能交付物 | E10: 陈明 | F10: 1. 编码、名称不可修改；2. 计量单位需有效；3. 保存后同步更新；4. 操作有日志记录；5. 禁用时弹出确认提示 | G10: 46041 | H10: 46041 | I10: 验收通过 | J10: 1.01-06 17:00（第 1 周）：初始 “待交付”；2.01-17 17:00（第 2 周）：依赖物料信息新增功能完成，启动开发，状态 “开发中”；3.01-18 17:00（第 2 周）：开发完成，状态更新为 “待验收”；4.01-19 17:00（第 2 周）：张伟验收通过 | K10: 已关联业务单据的物料禁用前需确认影响 | L10: PB-BD-023 | M10: MES-BD-23
A11: D-F-061 | B11: 物料信息删除（可运行） | C11: 基础数据（BD） | D11: 功能交付物 | E11: 陈明 | F11: 1. 删除前弹出确认提示；2. 已关联业务单据的禁止删除；3. 仅禁用状态可删除；4. 删除后不再显示；5. 操作有日志记录 | G11: 46042 | H11: 46042 | I11: 验收通过 | J11: 1.01-06 17:00（第 1 周）：初始 “待交付”；2.01-18 17:00（第 2 周）：依赖物料信息新增功能完成，启动开发，状态 “开发中”；3.01-19 17:00（第 2 周）：开发完成，状态更新为 “待验收”；4.01-20 17:00（第 2 周）：张伟验收通过 | K11: 建议删除前备份物料信息 | L11: PB-BD-024 | M11: MES-BD-24
A12: D-F-062 | B12: 物料 BOM 新增（可运行） | C12: 基础数据（BD） | D12: 功能交付物 | E12: 王强 | F12: 1. 必填项为空提示；2. 同一父物料 + 版本号唯一；3. 用量比例 > 0；4. 父 / 子物料需有效；5. 保存后列表同步显示 | G12: 46043 | H12: 46043 | I12: 验收通过 | J12: 1.01-06 17:00（第 1 周）：初始 “待交付”；2.01-19 17:00（第 2 周）：依赖物料信息新增功能完成，启动开发，状态 “开发中”；3.01-20 17:00（第 2 周）：开发完成，状态更新为 “待验收”；4.01-21 17:00（第 2 周）：张伟验收通过 | K12: BOM 版本号建议采用 “V+X.Y.Z” 格式 | L12: PB-BD-025 | M12: MES-BD-25
A13: D-F-063 | B13: 物料 BOM 查询（可运行） | C13: 基础数据（BD） | D13: 功能交付物 | E13: 王强 | F13: 1. 编码精确匹配，名称模糊匹配；2. 按版本号筛选，默认最新生效版本；3. 展示核心字段；4. 支持层级展开 / 折叠；5. 无结果提示对应信息 | G13: 46044 | H13: 46044 | I13: 验收通过 | J13: 1.01-06 17:00（第 1 周）：初始 “待交付”；2.01-20 17:00（第 2 周）：依赖物料 BOM 新增功能完成，启动开发，状态 “开发中”；3.01-21 17:00（第 2 周）：开发完成，状态更新为 “待验收”；4.01-22 17:00（第 2 周）：张伟验收通过 | K13: 支持导出 BOM 查询结果（Excel 格式） | L13: PB-BD-026 | M13: MES-BD-26
... A53: D-C-005 | B53: 迭代 2 后端接口代码 | C53: 全模块 | D53: 代码交付物 | E53: 王强 | F53: 1. 逻辑正确；2. 接口可用；3. 注释完整；4. 提交至 iter2-back 分支 | G53: 46048 | H53: 46048 | I53: 验收通过 | J53: 1.01-06 17:00（第 1 周）：初始 “待交付”；2.01-24 17:00（第 2 周）：完成 85%，状态更新为 “开发中”；3.01-25 17:00（第 2 周）：开发完成，状态更新为 “待验收”；4.01-26 17:00（第 2 周）：陈明数据库校验通过 | K53: 含销售、采购、设备、仓库模块接口实现 | L53: 无 | M53: 无

Sheet 交付状态统计
B2: 一、整体交付概览（截至 2026 年 1 月 26 日）
B3: 统计维度 | C3: 数量（项） / 占比 | D3: 明细说明
B4: 交付物总项数 | C4: =COUNTA(交付物清单!B2:B922) -> 52 | D4: ="含功能交付物"&COUNTIF(交付物清单!D2:D922,"功能交付物")&"项、文档交付物 "&COUNTIF(交付物清单!D2:D922,"文档交付物")&" 项、代码交付物 "&COUNTIF(交付物清单!D2:D922,"代码交付物")&" 项、配置交付物 "&COUNTIF(交付物清单!D2:D922,"配置交付物")&" 项" -> 含功能交付物48项、文档交付物 2 项、代码交付物 2 项、配置交付物 0 项
B5: 验收通过项数 | C5: =COUNTIF(交付物清单!I2:I922,"验收通过") -> 52 | D5: ="占比"&IF(C4=0,0,C5/C4)*100&"%" -> 占比100%
B6: 待验收项数 | C6: =COUNTIF(交付物清单!I2:I922,"待验收") -> 0 | D6: ="占比"&IF(C4=0,0,C6/C4)*100&"%" -> 占比0%
B7: 开发中项数 | C7: =COUNTIF(交付物清单!I2:I922,"开发中") -> 0 | D7: ="占比"&IF(C4=0,0,C7/C4)*100&"%" -> 占比0%
B8: 验收不通过项数 | C8: =COUNTIF(交付物清单!I2:I922,"验收不通过") -> 0 | D8: ="占比"&IF(C4=0,0,C8/C4)*100&"%" -> 占比0%
B9: 延迟交付项数 | C9: {=SUMPRODUCT(--(交付物清单!H2:H922>交付物清单!G2:G922),--(交付物清单!H2:H922<>""))} -> 0 | D9: ="占比"&IF(C4=0,0,C9/C4)*100&"%" -> 占比0%
B10: 整体完成率 | C10: =IF(C4=0,0,C5/C4) -> 1 | D10: 按“验收通过项数/总项数”计算
B18: 二、按模块交付统计
B19: 所属模块 | C19: 交付物总项数（项） | D19: 验收通过项数（项） | E19: 完成率 | F19: 未完成项说明（如有） | G19: 责任团队
B20: 系统管理（SM） | C20: =COUNTIF(交付物清单!C1:C921,"系统管理（SM）") -> 2 | D20: =COUNTIFS(交付物清单!C1:C921,"系统管理（SM）",交付物清单!I1:I921,"验收通过") -> 2 | E20: =IF(C20=0,0,D20/C20) -> 1 | F20: 无 | G20: 王强
B21: 设备管理（EQ） | C21: =COUNTIF(交付物清单!C2:C922,"设备管理（EQ）") -> 8 | D21: =COUNTIFS(交付物清单!C2:C922,"设备管理（EQ）",交付物清单!I2:I922,"验收通过") -> 8 | E21: =IF(C21=0,0,D21/C21) -> 1 | F21: 无 | G21: 刘婷、陈明
B22: 仓库管理（WH） | C22: =COUNTIF(交付物清单!C2:C922,"仓库管理（WH）") -> 6 | D22: =COUNTIFS(交付物清单!C2:C922,"仓库管理（WH）",交付物清单!I2:I922,"验收通过") -> 6 | E22: =IF(C22=0,0,D22/C22) -> 1 | F22: 无 | G22: 王强、陈明
B23: 基础数据（BD） | C23: =COUNTIF(交付物清单!C2:C922,"基础数据（BD）") -> 12 | D23: =COUNTIFS(交付物清单!C2:C922,"基础数据（BD）",交付物清单!I2:I922,"验收通过") -> 12 | E23: =IF(C23=0,0,D23/C23) -> 1 | F23: 无 | G23: 王强、刘婷、陈明
B24: 销售管理（SL） | C24: =COUNTIF(交付物清单!C2:C923,"销售管理（SL）") -> 10 | D24: =COUNTIFS(交付物清单!C2:C923,"销售管理（SL）",交付物清单!I2:I923,"验收通过") -> 10 | E24: =IF(C24=0,0,D24/C24) -> 1 | F24: 无 | G24: 王强、刘婷、陈明
B25: 采购管理（PO） | C25: =COUNTIF(交付物清单!C2:C924,"采购管理（PO）") -> 10 | D25: =COUNTIFS(交付物清单!C2:C924,"采购管理（PO）",交付物清单!I2:I924,"验收通过") -> 10 | E25: =IF(C25=0,0,D25/C25) -> 1 | F25: 无 | G25: 王强、刘婷、陈明
B26: 全模块 | C26: =COUNTIF(交付物清单!C4:C922,"全模块") -> 4 | D26: =COUNTIFS(交付物清单!C2:C922,"全模块",交付物清单!I2:I922,"验收通过") -> 4 | E26: =IF(C26=0,0,D26/C26) -> 1 | F26: 无 | G26: 赵燕、陈明、王强、孙涛
B27: 模块合计 | C27: =SUM(C20:C26) -> 52 | D27: =SUM(D20:D26) -> 52 | E27: =IF(C27=0,0,D27/C27) -> 1 | F27: - | G27: -
B30: 三、按交付类型统计
B31: 交付类型 | C31: 总项数（项） | D31: 验收通过项数（项） | E31: 完成率 | F31: 说明 | G31: 关键责任人
B32: 功能交付物 | C32: =COUNTIF(交付物清单!D2:D922,"功能交付物") -> 48 | D32: =COUNTIFS(交付物清单!D2:D922,"功能交付物",交付物清单!I2:I922,"验收通过") -> 48 | E32: =IF(C32=0,0,D32/C32) -> 1 | F32: 无 | G32: 刘婷、王强、陈明
B33: 文档交付物 | C33: =COUNTIF(交付物清单!D2:D922,"文档交付物") -> 2 | D33: =COUNTIFS(交付物清单!D2:D922,"文档交付物",交付物清单!I2:I922,"验收通过") -> 2 | E33: =IF(C33=0,0,D33/C33) -> 1 | F33: 无 | G33: 王强、孙涛、赵燕
B34: 代码交付物 | C34: =COUNTIF(交付物清单!D2:D922,"代码交付物") -> 2 | D34: =COUNTIFS(交付物清单!D2:D922,"代码交付物",交付物清单!I2:I922,"验收通过") -> 2 | E34: =IF(C34=0,0,D34/C34) -> 1 | F34: 无 | G34: 刘婷、王强、陈明
B35: 配置交付物 | C35: =COUNTIF(交付物清单!D2:D922,"配置交付物") -> 0 | D35: =COUNTIFS(交付物清单!D2:D922,"配置交付物",交付物清单!I2:I922,"验收通过") -> 0 | E35: =IF(C35=0,0,D35/C35) -> 0 | F35: 无 | G35: 王强、陈明
B36: 类型合计 | C36: =SUM(C32:C35) -> 52 | D36: =SUM(D32:D35) -> 52 | E36: =IF(C36=0,0,D36/C36) -> 1 | F36: - | G36: -
B39: 四、按周度交付统计（关键时间节点）
B40: 周度 | C40: 计划交付项数（项） | D40: 实际完成项数（项） | E40: 完成率 | F40: 延迟项说明 | G40: 本周核心成果
B41: 第一周（2026.1.6-1.12） | C41: =COUNTIFS(交付物清单!G2:G922,">="&DATE(2026,1,6),交付物清单!G2:G922,"<="&DATE(2026,1,12)) -> 6 | D41: =COUNTIFS(交付物清单!G2:G922,">="&DATE(2026,1,6),交付物清单!G2:G922,"<="&DATE(2026,1,12),交付物清单!I2:I922,"验收通过") -> 6 | E41: =IF(C41=0,0,D41/C41) -> 1 | F41: 无延迟 | G41: 1. 完成无依赖核心功能（角色新增、字典新增）； 2. 输出数据库设计文档、前端设计稿； 3. 完成第一周测试用例初稿
B44: 第二周（2026.1.13-1.19） | C44: =COUNTIFS(交付物清单!G2:G922,">="&DATE(2026,1,13),交付物清单!G2:G922,"<="&DATE(2026,1,19)) -> 25 | D44: =COUNTIFS(交付物清单!G2:G922,">="&DATE(2026,1,13),交付物清单!G2:G922,"<="&DATE(2026,1,19),交付物清单!I2:I922,"验收通过") -> 25 | E44: =IF(C44=0,0,D44/C44) -> 1 | F44: 无延迟 | G44: 1. 完成依赖类功能（用户新增、参数设置）； 2. 输出后端接口文档（80%）； 3. 完成基础数据维护功能开发
B47: 第三周（2026.1.20-2026.1.26） | C47: =COUNTIFS(交付物清单!G2:G922,">="&DATE(2026,1,20),交付物清单!G2:G922,"<="&DATE(2026,1,26)) -> 21 | D47: =COUNTIFS(交付物清单!G2:G922,">="&DATE(2026,1,20),交付物清单!G2:G922,"<="&DATE(2026,1,26),交付物清单!I2:I922,"验收通过") -> 21 | E47: =IF(C47=0,0,D47/C47) -> 1 | F47: 无延迟 | G47: 1. 完成功能集成测试与缺陷修复； 2. 输出迭代 1 测试报告（终稿）； 3. 完成所有代码提交与配置文件交付
B50: 周度合计 | C50: =SUM(C41:C49) -> 52 | D50: =SUM(D41:D49) -> 52 | E50: =IF(C50=0,0,D50/C50) -> 1 | F50: - | G50: -

Sheet 使用说明
B2: 交付物清单表格填写使用说明
B3: 适配文档版本 | C3: V1.1.0
B4: 生效日期 | C4: 46006
B5: 编制人 | C5: 李静（敏捷教练）
B6: 文档基础信息
B7: 项目 | C7: 说明
B8: 文档用途 | C8: 1. 跟踪迭代 1 全周期（2025.12.15-2026.01.05）所有交付物的开发、验收、归档进度；
C9: 2. 作为迭代评审会、项目归档的核心依据，确保交付物完整性与合规性；
C10: 3. 联动冲刺待办列表，避免 “任务完成但交付缺失” 的情况。
B11: 适用角色 | C11: 1. 责任认领人（刘婷 / 王强 / 陈明等）：更新交付进度、填写实际交付时间；
C12: 2. 维护人（李静）：每日同步状态、记录更新痕迹、解决填写冲突；
C13: 3. 验收人（张伟 / 王强 / 刘婷等）：验证交付物，填写验收结果；
C14: 4. 项目管理者：通过统计数据（Sheet3）监控迭代整体交付进度。
B15: 版本管理规则 | C15: 1. 若需新增 / 删除交付物，需同步更新 “交付物 ID”（按类型顺延编码，如新增功能交付物为 D-F-009）；
C16: 2. 版本更新需在 “文档基础信息” 栏标注 “修订版 Vx.x.x” 及修订日期，修订内容记录在 “常见问题处理” 后附的 “修订记录” 中；
C17: 3. 旧版本文档需存档，命名格式为 “迭代 1 交付物清单 Vx.x.x-YYYYMMDD.xlsx”。
B19: 交付清单字段填写规范
B20: 字段名称 | C20: 填写要求 | D20: 格式示例 | E20: 注意事项
B21: 交付物 ID* | C21: 固定编码，不可修改： | D21: D-F-004 | E21: 新增交付物需按类型顺延编码，不可重复
C22: - D-F：功能交付物（如 D-F-001）
C23: - D-D：文档交付物（如 D-D-001）
C24: - D-C：代码交付物（如 D-C-001）
C25: - D-CF：配置交付物（如 D-CF-001）
B26: 交付物名称 * | C26: 简洁描述交付物内容，与冲刺待办列表任务对应 | D26: 角色新增 / 修改 / 删除功能（可运行） | E26: 避免模糊表述（如不写 “角色相关功能”）
B27: 所属模块 * | C27: 按 “用户管理模块 / 系统配置模块 / 基础数据模块 / 项目管理” 四选一填写 | D27: 用户管理模块 | E27: 与冲刺待办列表的 “所属模块” 保持一致
B28: 交付类型 * | C28: 下拉选择：功能交付物/文档交付物/代码交付物/配置交付物 | D28: 功能交付物 | E28: 不可手动输入，需从预设选项中选择
B29: 责任认领人 * | C29: 填写姓名全称，与冲刺待办列表 “认领人” 一致 | D29: 刘婷 | E29: 多人协作需填写主要责任人（如 “王强 / 陈明”）
B30: 核心验收标准 * | C30: 提炼 3-5 条关键验收点，直接引用冲刺待办列表 “验收标准要点” | D30: 1. 角色名称空校验；2. 权限联动实时更新 | E30: 避免冗余，不写 “符合行业标准” 等模糊表述
B31: 计划交付时间 * | C31: 日期格式（YYYY-MM-DD），与迭代排期对齐 | D31: 46009 | E31: 需在迭代周期内（2025.12.15-2026.01.05）
B32: 实际交付时间 | C32: 交付物提交验收时填写，日期格式（YYYY-MM-DD） | D32: 46009 | E32: 未交付时留空，交付后 24 小时内填写
B33: 交付状态 * | C33: 下拉选择：待交付/开发中/待验收/验收通过/验收不通过 | D33: 验收通过 | E33: 状态流转需符合逻辑（如 “开发中”→“待验收”，不可跳至 “验收通过”）
B34: 更新记录 * | C34: 格式：“日期 时间：操作内容”，每次状态变更需新增一条记录 | D34: 12-18 17:00：张伟验收通过，状态更新为 “验收通过” | E34: 需注明操作人（如 “刘婷反馈”“张伟验收”），确保可追溯
B35: 备注 | C35: 填写特殊说明（如延迟原因、依赖关系、验收不通过的 bug 详情） | D35: 延迟 1 天（因核心字典删除漏洞修复） | E35: 无特殊情况时留空，不写无关信息
B37: 维护流程与分工
B38: 时间节点 | C38: 操作人 | D38: 核心动作 | E38: 输出结果
B39: 每日 9:30 站会前 | C39: 责任认领人 | D39: 检查负责的交付物状态，更新 “开发中” 进度（如 “开发中（80%）”），填写延迟原因（若有） | E39: 交付物状态与实际进度一致
B40: 每日 17:00 站会后 | C40: 李静（维护人） | D40: 1. 汇总责任认领人的更新，同步修改 “交付状态”； | E40: “更新记录” 完整，状态无遗漏
D41: 2. 记录更新痕迹（新增 “更新记录”）；
D42: 3. 标记延迟交付项（实际 > 计划）、验收不通过项
B43: 交付物提交后 24 小时内 | C43: 验收人 | D43: 验证交付物（如张伟验收功能、王强验收代码），反馈验收结果 | E43: “交付状态” 更新为 “验收通过” 或 “验收不通过”，“验收人” 填写姓名
...
